Workbook

Sheet Notes
B1: Aster Ridge (Demo) - .H Model - Notes
B2: Last updated 2026-07-29. Read before using this model.
B4: SYNTHETIC DEMO DATA
B5: Aster Ridge Senior Living is a FICTIONAL community. Every figure in this workbook is
B6: fabricated for a public process demonstration - see FABRICATION-SPEC.md in the deal folder.
B7: No real deal data anywhere in this file.
B9: MAPPING RULINGS - pipeline agents, 2026-07-29 demo build
B11: Pooled payroll taxes and benefits
B12: Operator GL pools 6710 Payroll Taxes / 6720 Employee Benefits company-wide (no department
B13: split). RULING: mapped to Benefits - Admin (no company-wide tag on the master list).
B14: IMPACT: departmental Benefits roll-up rows read 0; the full ,527/yr sits in Benefits -
B15: Admin; the payroll-burden metric is pooled-safe by construction (reads 16.85%). Do not
... B32: demo (no broker to query).

Sheet Aster Ridge.H (Review)
S2: 1 | T2: 2 | U2: 4
S3: T12 | T3: T6 | U3: T3
S4: =F5 -> 45869 | T4: =+EOMONTH(S4,6) -> 46053 | U4: =+EOMONTH(T4,3) -> 46142
F5: 45869 | G5: =EOMONTH(F5,1) -> 45900 | H5: =EOMONTH(G5,1) -> 45930 | I5: =EOMONTH(H5,1) -> 45961 | J5: =EOMONTH(I5,1) -> 45991 | K5: =EOMONTH(J5,1) -> 46022 | L5: =EOMONTH(K5,1) -> 46053 | M5: =EOMONTH(L5,1) -> 46081 | N5: =EOMONTH(M5,1) -> 46112 | ... Q5: =EOMONTH(P5,1) -> 46203 | S5: =Q5 -> 46203 | T5: =+S5 -> 46203 | U5: =+T5 -> 46203
D7: Days | F7: =DAY(EOMONTH(F5,0)) -> 31 | G7: =DAY(EOMONTH(G5,0)) -> 31 | H7: =DAY(EOMONTH(H5,0)) -> 30 | I7: =DAY(EOMONTH(I5,0)) -> 31 | J7: =DAY(EOMONTH(J5,0)) -> 30 | K7: =DAY(EOMONTH(K5,0)) -> 31 | L7: =DAY(EOMONTH(L5,0)) -> 31 | M7: =DAY(EOMONTH(M5,0)) -> 28 | ... Q7: =DAY(EOMONTH(Q5,0)) -> 30 | S7: =IFERROR(SUMIFS($E7:$Q7,$E$5:$Q$5,">="&S$4,$E$5:$Q$5,"<="&S$5),0)*S$2 -> 365 | T7: =IFERROR(SUMIFS($E7:$Q7,$E$5:$Q$5,">="&T$4,$E$5:$Q$5,"<="&T$5),0)*T$2 -> 362 | U7: =IFERROR(SUMIFS($E7:$Q7,$E$5:$Q$5,">="&U$4,$E$5:$Q$5,"<="&U$5),0)*U$2 -> 364
C9: Capacity | D9: IL | F9: =Census!E24 -> 40 | G9: =Census!F24 -> 40 | H9: =Census!G24 -> 40 | I9: =Census!H24 -> 40 | J9: =Census!I24 -> 40 | K9: =Census!J24 -> 40 | L9: =Census!K24 -> 40 | M9: =Census!L24 -> 40 | ... Q9: =Census!P24 -> 40 | S9: =+IFERROR(AVERAGEIFS($E9:$Q9,$E$5:$Q$5,">="&S$4,$E$5:$Q$5,"<="&S$5),"NA") -> 40 | T9: =+IFERROR(AVERAGEIFS($E9:$Q9,$E$5:$Q$5,">="&T$4,$E$5:$Q$5,"<="&T$5),"NA") -> 40 | U9: =+IFERROR(AVERAGEIFS($E9:$Q9,$E$5:$Q$5,">="&U$4,$E$5:$Q$5,"<="&U$5),"NA") -> 40
C10: Capacity | D10: AL | F10: =Census!E25 -> 30 | G10: =Census!F25 -> 30 | H10: =Census!G25 -> 30 | I10: =Census!H25 -> 30 | J10: =Census!I25 -> 30 | K10: =Census!J25 -> 30 | L10: =Census!K25 -> 30 | M10: =Census!L25 -> 30 | ... Q10: =Census!P25 -> 30 | S10: =+IFERROR(AVERAGEIFS($E10:$Q10,$E$5:$Q$5,">="&S$4,$E$5:$Q$5,"<="&S$5),"NA") -> 30 | T10: =+IFERROR(AVERAGEIFS($E10:$Q10,$E$5:$Q$5,">="&T$4,$E$5:$Q$5,"<="&T$5),"NA") -> 30 | U10: =+IFERROR(AVERAGEIFS($E10:$Q10,$E$5:$Q$5,">="&U$4,$E$5:$Q$5,"<="&U$5),"NA") -> 30
C11: Capacity | D11: MC | F11: =Census!E26 -> 14 | G11: =Census!F26 -> 14 | H11: =Census!G26 -> 14 | I11: =Census!H26 -> 14 | J11: =Census!I26 -> 14 | K11: =Census!J26 -> 14 | L11: =Census!K26 -> 14 | M11: =Census!L26 -> 14 | ... Q11: =Census!P26 -> 14 | S11: =+IFERROR(AVERAGEIFS($E11:$Q11,$E$5:$Q$5,">="&S$4,$E$5:$Q$5,"<="&S$5),"NA") -> 14 | T11: =+IFERROR(AVERAGEIFS($E11:$Q11,$E$5:$Q$5,">="&T$4,$E$5:$Q$5,"<="&T$5),"NA") -> 14 | U11: =+IFERROR(AVERAGEIFS($E11:$Q11,$E$5:$Q$5,">="&U$4,$E$5:$Q$5,"<="&U$5),"NA") -> 14
C12: Capacity | D12: Total | F12: =SUM(F9:F11) -> 84 | G12: =SUM(G9:G11) -> 84 | H12: =SUM(H9:H11) -> 84 | I12: =SUM(I9:I11) -> 84 | J12: =SUM(J9:J11) -> 84 | K12: =SUM(K9:K11) -> 84 | L12: =SUM(L9:L11) -> 84 | M12: =SUM(M9:M11) -> 84 | ... Q12: =SUM(Q9:Q11) -> 84 | S12: =+AVERAGEIFS($E12:$Q12,$E$5:$Q$5,">="&S$4,$E$5:$Q$5,"<="&S$5) -> 84 | T12: =+AVERAGEIFS($E12:$Q12,$E$5:$Q$5,">="&T$4,$E$5:$Q$5,"<="&T$5) -> 84 | U12: =+AVERAGEIFS($E12:$Q12,$E$5:$Q$5,">="&U$4,$E$5:$Q$5,"<="&U$5) -> 84
C14: Occupied | D14: IL | F14: =F19*F9 -> 34 | G14: =G19*G9 -> 34 | H14: =H19*H9 -> 35 | I14: =I19*I9 -> 35 | J14: =J19*J9 -> 36 | K14: =K19*K9 -> 36 | L14: =L19*L9 -> 36 | M14: =M19*M9 -> 35 | ... Q14: =Q19*Q9 -> 37 | S14: =+IFERROR(AVERAGEIFS($E14:$Q14,$E$5:$Q$5,">="&S$4,$E$5:$Q$5,"<="&S$5),"NA") -> 35.583333 | T14: =+IFERROR(AVERAGEIFS($E14:$Q14,$E$5:$Q$5,">="&T$4,$E$5:$Q$5,"<="&T$5),"NA") -> 36.166667 | U14: =+IFERROR(AVERAGEIFS($E14:$Q14,$E$5:$Q$5,">="&U$4,$E$5:$Q$5,"<="&U$5),"NA") -> 36.666667
C15: Occupied | D15: AL | F15: =F20*F10 -> 26 | G15: =G20*G10 -> 27 | H15: =H20*H10 -> 27 | I15: =I20*I10 -> 26 | J15: =J20*J10 -> 27 | K15: =K20*K10 -> 28 | L15: =L20*L10 -> 28 | M15: =M20*M10 -> 27 | ... Q15: =Q20*Q10 -> 28 | S15: =+IFERROR(AVERAGEIFS($E15:$Q15,$E$5:$Q$5,">="&S$4,$E$5:$Q$5,"<="&S$5),"NA") -> 27.25 | T15: =+IFERROR(AVERAGEIFS($E15:$Q15,$E$5:$Q$5,">="&T$4,$E$5:$Q$5,"<="&T$5),"NA") -> 27.666667 | U15: =+IFERROR(AVERAGEIFS($E15:$Q15,$E$5:$Q$5,">="&U$4,$E$5:$Q$5,"<="&U$5),"NA") -> 28
C16: Occupied | D16: MC | F16: =F21*F11 -> 11 | G16: =G21*G11 -> 12 | H16: =H21*H11 -> 12 | I16: =I21*I11 -> 12 | J16: =J21*J11 -> 13 | K16: =K21*K11 -> 12 | L16: =L21*L11 -> 12 | M16: =M21*M11 -> 13 | ... Q16: =Q21*Q11 -> 13 | S16: =+IFERROR(AVERAGEIFS($E16:$Q16,$E$5:$Q$5,">="&S$4,$E$5:$Q$5,"<="&S$5),"NA") -> 12.333333 | T16: =+IFERROR(AVERAGEIFS($E16:$Q16,$E$5:$Q$5,">="&T$4,$E$5:$Q$5,"<="&T$5),"NA") -> 12.666667 | U16: =+IFERROR(AVERAGEIFS($E16:$Q16,$E$5:$Q$5,">="&U$4,$E$5:$Q$5,"<="&U$5),"NA") -> 12.666667
C17: Occupied | D17: Total | F17: =SUM(F14:F16) -> 71 | G17: =SUM(G14:G16) -> 73 | H17: =SUM(H14:H16) -> 74 | I17: =SUM(I14:I16) -> 73 | J17: =SUM(J14:J16) -> 76 | K17: =SUM(K14:K16) -> 76 | L17: =SUM(L14:L16) -> 76 | M17: =SUM(M14:M16) -> 75 | ... Q17: =SUM(Q14:Q16) -> 78 | S17: =+AVERAGEIFS($E17:$Q17,$E$5:$Q$5,">="&S$4,$E$5:$Q$5,"<="&S$5) -> 75.166667 | T17: =+AVERAGEIFS($E17:$Q17,$E$5:$Q$5,">="&T$4,$E$5:$Q$5,"<="&T$5) -> 76.5 | U17: =+AVERAGEIFS($E17:$Q17,$E$5:$Q$5,">="&U$4,$E$5:$Q$5,"<="&U$5) -> 77.333333
C19: Occ % | D19: IL | F19: =Census!E34 -> 0.85 | G19: =Census!F34 -> 0.85 | H19: =Census!G34 -> 0.875 | I19: =Census!H34 -> 0.875 | J19: =Census!I34 -> 0.9 | K19: =Census!J34 -> 0.9 | L19: =Census!K34 -> 0.9 | M19: =Census!L34 -> 0.875 | ... Q19: =Census!P34 -> 0.925 | S19: =+IFERROR(S14/S9,"NA") -> 0.88958333 | T19: =+IFERROR(T14/T9,"NA") -> 0.90416667 | U19: =+IFERROR(U14/U9,"NA") -> 0.91666667
C20: Occ % | D20: AL | F20: =Census!E35 -> 0.86666667 | G20: =Census!F35 -> 0.9 | H20: =Census!G35 -> 0.9 | I20: =Census!H35 -> 0.86666667 | J20: =Census!I35 -> 0.9 | K20: =Census!J35 -> 0.93333333 | L20: =Census!K35 -> 0.93333333 | M20: =Census!L35 -> 0.9 | ... Q20: =Census!P35 -> 0.93333333 | S20: =+IFERROR(S15/S10,"NA") -> 0.90833333 | T20: =+IFERROR(T15/T10,"NA") -> 0.92222222 | U20: =+IFERROR(U15/U10,"NA") -> 0.93333333
C21: Occ % | D21: MC | F21: =Census!E36 -> 0.78571429 | G21: =Census!F36 -> 0.85714286 | H21: =Census!G36 -> 0.85714286 | I21: =Census!H36 -> 0.85714286 | J21: =Census!I36 -> 0.92857143 | K21: =Census!J36 -> 0.85714286 | L21: =Census!K36 -> 0.85714286 | M21: =Census!L36 -> 0.92857143 | ... Q21: =Census!P36 -> 0.92857143 | S21: =+IFERROR(S16/S11,"NA") -> 0.88095238 | T21: =+IFERROR(T16/T11,"NA") -> 0.9047619 | U21: =+IFERROR(U16/U11,"NA") -> 0.9047619
C22: Occ % | D22: Total | F22: =+IFERROR(F17/F12,"NA") -> 0.8452381 | G22: =+IFERROR(G17/G12,"NA") -> 0.86904762 | H22: =+IFERROR(H17/H12,"NA") -> 0.88095238 | I22: =+IFERROR(I17/I12,"NA") -> 0.86904762 | J22: =+IFERROR(J17/J12,"NA") -> 0.9047619 | K22: =+IFERROR(K17/K12,"NA") -> 0.9047619 | L22: =+IFERROR(L17/L12,"NA") -> 0.9047619 | M22: =+IFERROR(M17/M12,"NA") -> 0.89285714 | ... Q22: =+IFERROR(Q17/Q12,"NA") -> 0.92857143 | S22: =+IFERROR(S17/S12,"NA") -> 0.89484127 | T22: =+IFERROR(T17/T12,"NA") -> 0.91071429 | U22: =+IFERROR(U17/U12,"NA") -> 0.92063492
D24: PRD | F24: =+F17*F7*F199 -> 2201 | G24: =+G17*G7*G199 -> 2263 | H24: =+H17*H7*H199 -> 2220 | I24: =+I17*I7*I199 -> 2263 | J24: =+J17*J7*J199 -> 2280 | K24: =+K17*K7*K199 -> 2356 | L24: =+L17*L7*L199 -> 2356 | M24: =+M17*M7*M199 -> 2100 | ... Q24: =+Q17*Q7*Q199 -> 2340 | S24: =IFERROR(SUMIFS($E24:$Q24,$E$5:$Q$5,">="&S$4,$E$5:$Q$5,"<="&S$5),0)*S$2 -> 27433 | T24: =IFERROR(SUMIFS($E24:$Q24,$E$5:$Q$5,">="&T$4,$E$5:$Q$5,"<="&T$5),0)*T$2 -> 27700 | U24: =IFERROR(SUMIFS($E24:$Q24,$E$5:$Q$5,">="&U$4,$E$5:$Q$5,"<="&U$5),0)*U$2 -> 28152
D26: REVENUE
B28: =_xlfn.LET(_xlpm.r,_xlfn.XLOOKUP(D28,'AR PnL Mapping'!$C$3:$C$60,'AR PnL Mapping'!$B$3:$B$60,""),IF(OR(_xlpm.r="",_xlpm.r=0),"",_xlpm.r)) -> Rent Revenue - IL | D28: 4010 - Rent Income - IL | F28: =_xlfn.XLOOKUP($D28,'AR Historical Financials'!$C$8:$C$93,'AR Historical Financials'!E$8:E$93) -> 130152 | G28: =_xlfn.XLOOKUP($D28,'AR Historical Financials'!$C$8:$C$93,'AR Historical Financials'!F$8:F$93) -> 130398 | H28: =_xlfn.XLOOKUP($D28,'AR Historical Financials'!$C$8:$C$93,'AR Historical Financials'!G$8:G$93) -> 133507 | I28: =_xlfn.XLOOKUP($D28,'AR Historical Financials'!$C$8:$C$93,'AR Historical Financials'!H$8:H$93) -> 132350 | J28: =_xlfn.XLOOKUP($D28,'AR Historical Financials'!$C$8:$C$93,'AR Historical Financials'!I$8:I$93) -> 135400 | K28: =_xlfn.XLOOKUP($D28,'AR Historical Financials'!$C$8:$C$93,'AR Historical Financials'!J$8:J$93) -> 135680 | L28: =_xlfn.XLOOKUP($D28,'AR Historical Financials'!$C$8:$C$93,'AR Historical Financials'!K$8:K$93) -> 136760 | M28: =_xlfn.XLOOKUP($D28,'AR Historical Financials'!$C$8:$C$93,'AR Historical Financials'!L$8:L$93) -> 133994 | ... Q28: =_xlfn.XLOOKUP($D28,'AR Historical Financials'!$C$8:$C$93,'AR Historical Financials'!P$8:P$93) -> 140535 | S28: =IFERROR(SUMIFS($E28:$Q28,$E$5:$Q$5,">="&S$4,$E$5:$Q$5,"<="&S$5),0)*S$2 -> 1624031 | T28: =IFERROR(SUMIFS($E28:$Q28,$E$5:$Q$5,">="&T$4,$E$5:$Q$5,"<="&T$5),0)*T$2 -> 1653088 | U28: =IFERROR(SUMIFS($E28:$Q28,$E$5:$Q$5,">="&U$4,$E$5:$Q$5,"<="&U$5),0)*U$2 -> 1670908
B29: =_xlfn.LET(_xlpm.r,_xlfn.XLOOKUP(D29,'AR PnL Mapping'!$C$3:$C$60,'AR PnL Mapping'!$B$3:$B$60,""),IF(OR(_xlpm.r="",_xlpm.r=0),"",_xlpm.r)) -> Rent Revenue - AL | D29: 4020 - Rent Income - AL | F29: =_xlfn.XLOOKUP($D29,'AR Historical Financials'!$C$8:$C$93,'AR Historical Financials'!E$8:E$93) -> 120910 | G29: =_xlfn.XLOOKUP($D29,'AR Historical Financials'!$C$8:$C$93,'AR Historical Financials'!F$8:F$93) -> 125160 | H29: =_xlfn.XLOOKUP($D29,'AR Historical Financials'!$C$8:$C$93,'AR Historical Financials'!G$8:G$93) -> 124124 | I29: =_xlfn.XLOOKUP($D29,'AR Historical Financials'!$C$8:$C$93,'AR Historical Financials'!H$8:H$93) -> 118673 | J29: =_xlfn.XLOOKUP($D29,'AR Historical Financials'!$C$8:$C$93,'AR Historical Financials'!I$8:I$93) -> 123170 | K29: =_xlfn.XLOOKUP($D29,'AR Historical Financials'!$C$8:$C$93,'AR Historical Financials'!J$8:J$93) -> 128565 | L29: =_xlfn.XLOOKUP($D29,'AR Historical Financials'!$C$8:$C$93,'AR Historical Financials'!K$8:K$93) -> 129671 | M29: =_xlfn.XLOOKUP($D29,'AR Historical Financials'!$C$8:$C$93,'AR Historical Financials'!L$8:L$93) -> 125562 | ... Q29: =_xlfn.XLOOKUP($D29,'AR Historical Financials'!$C$8:$C$93,'AR Historical Financials'!P$8:P$93) -> 128925 | S29: =IFERROR(SUMIFS($E29:$Q29,$E$5:$Q$5,">="&S$4,$E$5:$Q$5,"<="&S$5),0)*S$2 -> 1506396 | T29: =IFERROR(SUMIFS($E29:$Q29,$E$5:$Q$5,">="&T$4,$E$5:$Q$5,"<="&T$5),0)*T$2 -> 1531588 | U29: =IFERROR(SUMIFS($E29:$Q29,$E$5:$Q$5,">="&U$4,$E$5:$Q$5,"<="&U$5),0)*U$2 -> 1541664
B30: =_xlfn.LET(_xlpm.r,_xlfn.XLOOKUP(D30,'AR PnL Mapping'!$C$3:$C$60,'AR PnL Mapping'!$B$3:$B$60,""),IF(OR(_xlpm.r="",_xlpm.r=0),"",_xlpm.r)) -> Rent Revenue - MC | D30: 4030 - Rent Income - MC | F30: =_xlfn.XLOOKUP($D30,'AR Historical Financials'!$C$8:$C$93,'AR Historical Financials'!E$8:E$93) -> 86707 | G30: =_xlfn.XLOOKUP($D30,'AR Historical Financials'!$C$8:$C$93,'AR Historical Financials'!F$8:F$93) -> 93912 | H30: =_xlfn.XLOOKUP($D30,'AR Historical Financials'!$C$8:$C$93,'AR Historical Financials'!G$8:G$93) -> 93135 | I30: =_xlfn.XLOOKUP($D30,'AR Historical Financials'!$C$8:$C$93,'AR Historical Financials'!H$8:H$93) -> 92846 | J30: =_xlfn.XLOOKUP($D30,'AR Historical Financials'!$C$8:$C$93,'AR Historical Financials'!I$8:I$93) -> 101036 | K30: =_xlfn.XLOOKUP($D30,'AR Historical Financials'!$C$8:$C$93,'AR Historical Financials'!J$8:J$93) -> 94072 | L30: =_xlfn.XLOOKUP($D30,'AR Historical Financials'!$C$8:$C$93,'AR Historical Financials'!K$8:K$93) -> 94660 | M30: =_xlfn.XLOOKUP($D30,'AR Historical Financials'!$C$8:$C$93,'AR Historical Financials'!L$8:L$93) -> 102463 | ... Q30: =_xlfn.XLOOKUP($D30,'AR Historical Financials'!$C$8:$C$93,'AR Historical Financials'!P$8:P$93) -> 101595 | S30: =IFERROR(SUMIFS($E30:$Q30,$E$5:$Q$5,">="&S$4,$E$5:$Q$5,"<="&S$5),0)*S$2 -> 1155856 | T30: =IFERROR(SUMIFS($E30:$Q30,$E$5:$Q$5,">="&T$4,$E$5:$Q$5,"<="&T$5),0)*T$2 -> 1188296 | U30: =IFERROR(SUMIFS($E30:$Q30,$E$5:$Q$5,">="&U$4,$E$5:$Q$5,"<="&U$5),0)*U$2 -> 1181216
B32: =_xlfn.LET(_xlpm.r,_xlfn.XLOOKUP(D32,'AR PnL Mapping'!$C$3:$C$60,'AR PnL Mapping'!$B$3:$B$60,""),IF(OR(_xlpm.r="",_xlpm.r=0),"",_xlpm.r)) | D32: TOTAL RENT REVENUE | F32: =_xlfn.XLOOKUP($D32,'AR Historical Financials'!$C$8:$C$93,'AR Historical Financials'!E$8:E$93) -> 337769 | G32: =_xlfn.XLOOKUP($D32,'AR Historical Financials'!$C$8:$C$93,'AR Historical Financials'!F$8:F$93) -> 349470 | H32: =_xlfn.XLOOKUP($D32,'AR Historical Financials'!$C$8:$C$93,'AR Historical Financials'!G$8:G$93) -> 350766 | I32: =_xlfn.XLOOKUP($D32,'AR Historical Financials'!$C$8:$C$93,'AR Historical Financials'!H$8:H$93) -> 343869 | J32: =_xlfn.XLOOKUP($D32,'AR Historical Financials'!$C$8:$C$93,'AR Historical Financials'!I$8:I$93) -> 359606 | K32: =_xlfn.XLOOKUP($D32,'AR Historical Financials'!$C$8:$C$93,'AR Historical Financials'!J$8:J$93) -> 358317 | L32: =_xlfn.XLOOKUP($D32,'AR Historical Financials'!$C$8:$C$93,'AR Historical Financials'!K$8:K$93) -> 361091 | M32: =_xlfn.XLOOKUP($D32,'AR Historical Financials'!$C$8:$C$93,'AR Historical Financials'!L$8:L$93) -> 362019 | ... Q32: =_xlfn.XLOOKUP($D32,'AR Historical Financials'!$C$8:$C$93,'AR Historical Financials'!P$8:P$93) -> 371055 | S32: =IFERROR(SUMIFS($E32:$Q32,$E$5:$Q$5,">="&S$4,$E$5:$Q$5,"<="&S$5),0)*S$2 -> 4286283 | T32: =IFERROR(SUMIFS($E32:$Q32,$E$5:$Q$5,">="&T$4,$E$5:$Q$5,"<="&T$5),0)*T$2 -> 4372972 | U32: =IFERROR(SUMIFS($E32:$Q32,$E$5:$Q$5,">="&U$4,$E$5:$Q$5,"<="&U$5),0)*U$2 -> 4393788
B34: =_xlfn.LET(_xlpm.r,_xlfn.XLOOKUP(D34,'AR PnL Mapping'!$C$3:$C$60,'AR PnL Mapping'!$B$3:$B$60,""),IF(OR(_xlpm.r="",_xlpm.r=0),"",_xlpm.r)) -> Care Revenue - AL | D34: 4110 - Care Level Income - AL | F34: =_xlfn.XLOOKUP($D34,'AR Historical Financials'!$C$8:$C$93,'AR Historical Financials'!E$8:E$93) -> 25794 | G34: =_xlfn.XLOOKUP($D34,'AR Historical Financials'!$C$8:$C$93,'AR Historical Financials'!F$8:F$93) -> 26554 | H34: =_xlfn.XLOOKUP($D34,'AR Historical Financials'!$C$8:$C$93,'AR Historical Financials'!G$8:G$93) -> 26411 | I34: =_xlfn.XLOOKUP($D34,'AR Historical Financials'!$C$8:$C$93,'AR Historical Financials'!H$8:H$93) -> 25486 | J34: =_xlfn.XLOOKUP($D34,'AR Historical Financials'!$C$8:$C$93,'AR Historical Financials'!I$8:I$93) -> 26677 | K34: =_xlfn.XLOOKUP($D34,'AR Historical Financials'!$C$8:$C$93,'AR Historical Financials'!J$8:J$93) -> 27880 | L34: =_xlfn.XLOOKUP($D34,'AR Historical Financials'!$C$8:$C$93,'AR Historical Financials'!K$8:K$93) -> 27928 | M34: =_xlfn.XLOOKUP($D34,'AR Historical Financials'!$C$8:$C$93,'AR Historical Financials'!L$8:L$93) -> 26782 | ... Q34: =_xlfn.XLOOKUP($D34,'AR Historical Financials'!$C$8:$C$93,'AR Historical Financials'!P$8:P$93) -> 27660 | S34: =IFERROR(SUMIFS($E34:$Q34,$E$5:$Q$5,">="&S$4,$E$5:$Q$5,"<="&S$5),0)*S$2 -> 322560 | T34: =IFERROR(SUMIFS($E34:$Q34,$E$5:$Q$5,">="&T$4,$E$5:$Q$5,"<="&T$5),0)*T$2 -> 327516 | U34: =IFERROR(SUMIFS($E34:$Q34,$E$5:$Q$5,">="&U$4,$E$5:$Q$5,"<="&U$5),0)*U$2 -> 329992
B35: =_xlfn.LET(_xlpm.r,_xlfn.XLOOKUP(D35,'AR PnL Mapping'!$C$3:$C$60,'AR PnL Mapping'!$B$3:$B$60,""),IF(OR(_xlpm.r="",_xlpm.r=0),"",_xlpm.r)) -> Care Revenue - MC | D35: 4120 - Care Level Income - MC | F35: =_xlfn.XLOOKUP($D35,'AR Historical Financials'!$C$8:$C$93,'AR Historical Financials'!E$8:E$93) -> 15207 | G35: =_xlfn.XLOOKUP($D35,'AR Historical Financials'!$C$8:$C$93,'AR Historical Financials'!F$8:F$93) -> 16471 | H35: =_xlfn.XLOOKUP($D35,'AR Historical Financials'!$C$8:$C$93,'AR Historical Financials'!G$8:G$93) -> 16462 | I35: =_xlfn.XLOOKUP($D35,'AR Historical Financials'!$C$8:$C$93,'AR Historical Financials'!H$8:H$93) -> 16569 | J35: =_xlfn.XLOOKUP($D35,'AR Historical Financials'!$C$8:$C$93,'AR Historical Financials'!I$8:I$93) -> 18104 | K35: =_xlfn.XLOOKUP($D35,'AR Historical Financials'!$C$8:$C$93,'AR Historical Financials'!J$8:J$93) -> 16781 | L35: =_xlfn.XLOOKUP($D35,'AR Historical Financials'!$C$8:$C$93,'AR Historical Financials'!K$8:K$93) -> 16726 | M35: =_xlfn.XLOOKUP($D35,'AR Historical Financials'!$C$8:$C$93,'AR Historical Financials'!L$8:L$93) -> 17969 | ... Q35: =_xlfn.XLOOKUP($D35,'AR Historical Financials'!$C$8:$C$93,'AR Historical Financials'!P$8:P$93) -> 18000 | S35: =IFERROR(SUMIFS($E35:$Q35,$E$5:$Q$5,">="&S$4,$E$5:$Q$5,"<="&S$5),0)*S$2 -> 204547 | T35: =IFERROR(SUMIFS($E35:$Q35,$E$5:$Q$5,">="&T$4,$E$5:$Q$5,"<="&T$5),0)*T$2 -> 209906 | U35: =IFERROR(SUMIFS($E35:$Q35,$E$5:$Q$5,">="&U$4,$E$5:$Q$5,"<="&U$5),0)*U$2 -> 209664
B37: =_xlfn.LET(_xlpm.r,_xlfn.XLOOKUP(D37,'AR PnL Mapping'!$C$3:$C$60,'AR PnL Mapping'!$B$3:$B$60,""),IF(OR(_xlpm.r="",_xlpm.r=0),"",_xlpm.r)) | D37: TOTAL CARE REVENUE | F37: =_xlfn.XLOOKUP($D37,'AR Historical Financials'!$C$8:$C$93,'AR Historical Financials'!E$8:E$93) -> 41001 | G37: =_xlfn.XLOOKUP($D37,'AR Historical Financials'!$C$8:$C$93,'AR Historical Financials'!F$8:F$93) -> 43025 | H37: =_xlfn.XLOOKUP($D37,'AR Historical Financials'!$C$8:$C$93,'AR Historical Financials'!G$8:G$93) -> 42873 | I37: =_xlfn.XLOOKUP($D37,'AR Historical Financials'!$C$8:$C$93,'AR Historical Financials'!H$8:H$93) -> 42055 | J37: =_xlfn.XLOOKUP($D37,'AR Historical Financials'!$C$8:$C$93,'AR Historical Financials'!I$8:I$93) -> 44781 | K37: =_xlfn.XLOOKUP($D37,'AR Historical Financials'!$C$8:$C$93,'AR Historical Financials'!J$8:J$93) -> 44661 | L37: =_xlfn.XLOOKUP($D37,'AR Historical Financials'!$C$8:$C$93,'AR Historical Financials'!K$8:K$93) -> 44654 | M37: =_xlfn.XLOOKUP($D37,'AR Historical Financials'!$C$8:$C$93,'AR Historical Financials'!L$8:L$93) -> 44751 | ... Q37: =_xlfn.XLOOKUP($D37,'AR Historical Financials'!$C$8:$C$93,'AR Historical Financials'!P$8:P$93) -> 45660 | S37: =IFERROR(SUMIFS($E37:$Q37,$E$5:$Q$5,">="&S$4,$E$5:$Q$5,"<="&S$5),0)*S$2 -> 527107 | T37: =IFERROR(SUMIFS($E37:$Q37,$E$5:$Q$5,">="&T$4,$E$5:$Q$5,"<="&T$5),0)*T$2 -> 537422 | U37: =IFERROR(SUMIFS($E37:$Q37,$E$5:$Q$5,">="&U$4,$E$5:$Q$5,"<="&U$5),0)*U$2 -> 539656
B39: =_xlfn.LET(_xlpm.r,_xlfn.XLOOKUP(D39,'AR PnL Mapping'!$C$3:$C$60,'AR PnL Mapping'!$B$3:$B$60,""),IF(OR(_xlpm.r="",_xlpm.r=0),"",_xlpm.r)) -> Rent - Second Person | D39: 4210 - Second Person Fees | F39: =_xlfn.XLOOKUP($D39,'AR Historical Financials'!$C$8:$C$93,'AR Historical Financials'!E$8:E$93) -> 7297 | G39: =_xlfn.XLOOKUP($D39,'AR Historical Financials'!$C$8:$C$93,'AR Historical Financials'!F$8:F$93) -> 7396 | H39: =_xlfn.XLOOKUP($D39,'AR Historical Financials'!$C$8:$C$93,'AR Historical Financials'!G$8:G$93) -> 7551 | I39: =_xlfn.XLOOKUP($D39,'AR Historical Financials'!$C$8:$C$93,'AR Historical Financials'!H$8:H$93) -> 7493 | J39: =_xlfn.XLOOKUP($D39,'AR Historical Financials'!$C$8:$C$93,'AR Historical Financials'!I$8:I$93) -> 7787 | K39: =_xlfn.XLOOKUP($D39,'AR Historical Financials'!$C$8:$C$93,'AR Historical Financials'!J$8:J$93) -> 7905 | L39: =_xlfn.XLOOKUP($D39,'AR Historical Financials'!$C$8:$C$93,'AR Historical Financials'!K$8:K$93) -> 7847 | M39: =_xlfn.XLOOKUP($D39,'AR Historical Financials'!$C$8:$C$93,'AR Historical Financials'!L$8:L$93) -> 7539 | ... Q39: =_xlfn.XLOOKUP($D39,'AR Historical Financials'!$C$8:$C$93,'AR Historical Financials'!P$8:P$93) -> 7960 | S39: =IFERROR(SUMIFS($E39:$Q39,$E$5:$Q$5,">="&S$4,$E$5:$Q$5,"<="&S$5),0)*S$2 -> 92194 | T39: =IFERROR(SUMIFS($E39:$Q39,$E$5:$Q$5,">="&T$4,$E$5:$Q$5,"<="&T$5),0)*T$2 -> 93530 | U39: =IFERROR(SUMIFS($E39:$Q39,$E$5:$Q$5,">="&U$4,$E$5:$Q$5,"<="&U$5),0)*U$2 -> 94964
B40: =_xlfn.LET(_xlpm.r,_xlfn.XLOOKUP(D40,'AR PnL Mapping'!$C$3:$C$60,'AR PnL Mapping'!$B$3:$B$60,""),IF(OR(_xlpm.r="",_xlpm.r=0),"",_xlpm.r)) -> Community Fees | D40: 4310 - Community Fees | F40: =_xlfn.XLOOKUP($D40,'AR Historical Financials'!$C$8:$C$93,'AR Historical Financials'!E$8:E$93) -> 4087 | G40: =_xlfn.XLOOKUP($D40,'AR Historical Financials'!$C$8:$C$93,'AR Historical Financials'!F$8:F$93) -> 9901 | H40: =_xlfn.XLOOKUP($D40,'AR Historical Financials'!$C$8:$C$93,'AR Historical Financials'!G$8:G$93) -> 5616 | I40: =_xlfn.XLOOKUP($D40,'AR Historical Financials'!$C$8:$C$93,'AR Historical Financials'!H$8:H$93) -> 3000 | J40: =_xlfn.XLOOKUP($D40,'AR Historical Financials'!$C$8:$C$93,'AR Historical Financials'!I$8:I$93) -> 13391 | K40: =_xlfn.XLOOKUP($D40,'AR Historical Financials'!$C$8:$C$93,'AR Historical Financials'!J$8:J$93) -> 3969 | L40: =_xlfn.XLOOKUP($D40,'AR Historical Financials'!$C$8:$C$93,'AR Historical Financials'!K$8:K$93) -> 3000 | M40: =_xlfn.XLOOKUP($D40,'AR Historical Financials'!$C$8:$C$93,'AR Historical Financials'!L$8:L$93) -> 3000 | ... Q40: =_xlfn.XLOOKUP($D40,'AR Historical Financials'!$C$8:$C$93,'AR Historical Financials'!P$8:P$93) -> 3000 | S40: =IFERROR(SUMIFS($E40:$Q40,$E$5:$Q$5,">="&S$4,$E$5:$Q$5,"<="&S$5),0)*S$2 -> 69359 | T40: =IFERROR(SUMIFS($E40:$Q40,$E$5:$Q$5,">="&T$4,$E$5:$Q$5,"<="&T$5),0)*T$2 -> 58790 | U40: =IFERROR(SUMIFS($E40:$Q40,$E$5:$Q$5,">="&U$4,$E$5:$Q$5,"<="&U$5),0)*U$2 -> 67860
B41: =_xlfn.LET(_xlpm.r,_xlfn.XLOOKUP(D41,'AR PnL Mapping'!$C$3:$C$60,'AR PnL Mapping'!$B$3:$B$60,""),IF(OR(_xlpm.r="",_xlpm.r=0),"",_xlpm.r)) -> Other Revenue | D41: 4410 - Other Resident Income | F41: =_xlfn.XLOOKUP($D41,'AR Historical Financials'!$C$8:$C$93,'AR Historical Financials'!E$8:E$93) -> 3577 | G41: =_xlfn.XLOOKUP($D41,'AR Historical Financials'!$C$8:$C$93,'AR Historical Financials'!F$8:F$93) -> 3254 | H41: =_xlfn.XLOOKUP($D41,'AR Historical Financials'!$C$8:$C$93,'AR Historical Financials'!G$8:G$93) -> 2852 | I41: =_xlfn.XLOOKUP($D41,'AR Historical Financials'!$C$8:$C$93,'AR Historical Financials'!H$8:H$93) -> 2960 | J41: =_xlfn.XLOOKUP($D41,'AR Historical Financials'!$C$8:$C$93,'AR Historical Financials'!I$8:I$93) -> 3420 | K41: =_xlfn.XLOOKUP($D41,'AR Historical Financials'!$C$8:$C$93,'AR Historical Financials'!J$8:J$93) -> 3557 | L41: =_xlfn.XLOOKUP($D41,'AR Historical Financials'!$C$8:$C$93,'AR Historical Financials'!K$8:K$93) -> 3171 | M41: =_xlfn.XLOOKUP($D41,'AR Historical Financials'!$C$8:$C$93,'AR Historical Financials'!L$8:L$93) -> 2827 | ... Q41: =_xlfn.XLOOKUP($D41,'AR Historical Financials'!$C$8:$C$93,'AR Historical Financials'!P$8:P$93) -> 3091 | S41: =IFERROR(SUMIFS($E41:$Q41,$E$5:$Q$5,">="&S$4,$E$5:$Q$5,"<="&S$5),0)*S$2 -> 38740 | T41: =IFERROR(SUMIFS($E41:$Q41,$E$5:$Q$5,">="&T$4,$E$5:$Q$5,"<="&T$5),0)*T$2 -> 38240 | U41: =IFERROR(SUMIFS($E41:$Q41,$E$5:$Q$5,">="&U$4,$E$5:$Q$5,"<="&U$5),0)*U$2 -> 40372
B42: =_xlfn.LET(_xlpm.r,_xlfn.XLOOKUP(D42,'AR PnL Mapping'!$C$3:$C$60,'AR PnL Mapping'!$B$3:$B$60,""),IF(OR(_xlpm.r="",_xlpm.r=0),"",_xlpm.r)) -> Other Revenue | D42: 4510 - Guest Meals & Ancillary | F42: =_xlfn.XLOOKUP($D42,'AR Historical Financials'!$C$8:$C$93,'AR Historical Financials'!E$8:E$93) -> 2517 | G42: =_xlfn.XLOOKUP($D42,'AR Historical Financials'!$C$8:$C$93,'AR Historical Financials'!F$8:F$93) -> 1915 | H42: =_xlfn.XLOOKUP($D42,'AR Historical Financials'!$C$8:$C$93,'AR Historical Financials'!G$8:G$93) -> 2183 | I42: =_xlfn.XLOOKUP($D42,'AR Historical Financials'!$C$8:$C$93,'AR Historical Financials'!H$8:H$93) -> 2715 | J42: =_xlfn.XLOOKUP($D42,'AR Historical Financials'!$C$8:$C$93,'AR Historical Financials'!I$8:I$93) -> 2310 | K42: =_xlfn.XLOOKUP($D42,'AR Historical Financials'!$C$8:$C$93,'AR Historical Financials'!J$8:J$93) -> 1882 | L42: =_xlfn.XLOOKUP($D42,'AR Historical Financials'!$C$8:$C$93,'AR Historical Financials'!K$8:K$93) -> 2397 | M42: =_xlfn.XLOOKUP($D42,'AR Historical Financials'!$C$8:$C$93,'AR Historical Financials'!L$8:L$93) -> 2693 | ... Q42: =_xlfn.XLOOKUP($D42,'AR Historical Financials'!$C$8:$C$93,'AR Historical Financials'!P$8:P$93) -> 2568 | S42: =IFERROR(SUMIFS($E42:$Q42,$E$5:$Q$5,">="&S$4,$E$5:$Q$5,"<="&S$5),0)*S$2 -> 27826 | T42: =IFERROR(SUMIFS($E42:$Q42,$E$5:$Q$5,">="&T$4,$E$5:$Q$5,"<="&T$5),0)*T$2 -> 28608 | U42: =IFERROR(SUMIFS($E42:$Q42,$E$5:$Q$5,">="&U$4,$E$5:$Q$5,"<="&U$5),0)*U$2 -> 28448
B44: =_xlfn.LET(_xlpm.r,_xlfn.XLOOKUP(D44,'AR PnL Mapping'!$C$3:$C$60,'AR PnL Mapping'!$B$3:$B$60,""),IF(OR(_xlpm.r="",_xlpm.r=0),"",_xlpm.r)) | D44: TOTAL OTHER REVENUE | F44: =_xlfn.XLOOKUP($D44,'AR Historical Financials'!$C$8:$C$93,'AR Historical Financials'!E$8:E$93) -> 17478 | G44: =_xlfn.XLOOKUP($D44,'AR Historical Financials'!$C$8:$C$93,'AR Historical Financials'!F$8:F$93) -> 22466 | H44: =_xlfn.XLOOKUP($D44,'AR Historical Financials'!$C$8:$C$93,'AR Historical Financials'!G$8:G$93) -> 18202 | I44: =_xlfn.XLOOKUP($D44,'AR Historical Financials'!$C$8:$C$93,'AR Historical Financials'!H$8:H$93) -> 16168 | J44: =_xlfn.XLOOKUP($D44,'AR Historical Financials'!$C$8:$C$93,'AR Historical Financials'!I$8:I$93) -> 26908 | K44: =_xlfn.XLOOKUP($D44,'AR Historical Financials'!$C$8:$C$93,'AR Historical Financials'!J$8:J$93) -> 17313 | L44: =_xlfn.XLOOKUP($D44,'AR Historical Financials'!$C$8:$C$93,'AR Historical Financials'!K$8:K$93) -> 16415 | M44: =_xlfn.XLOOKUP($D44,'AR Historical Financials'!$C$8:$C$93,'AR Historical Financials'!L$8:L$93) -> 16059 | ... Q44: =_xlfn.XLOOKUP($D44,'AR Historical Financials'!$C$8:$C$93,'AR Historical Financials'!P$8:P$93) -> 16619 | S44: =IFERROR(SUMIFS($E44:$Q44,$E$5:$Q$5,">="&S$4,$E$5:$Q$5,"<="&S$5),0)*S$2 -> 228119 | T44: =IFERROR(SUMIFS($E44:$Q44,$E$5:$Q$5,">="&T$4,$E$5:$Q$5,"<="&T$5),0)*T$2 -> 219168 | U44: =IFERROR(SUMIFS($E44:$Q44,$E$5:$Q$5,">="&U$4,$E$5:$Q$5,"<="&U$5),0)*U$2 -> 231644
... B112: =_xlfn.LET(_xlpm.r,_xlfn.XLOOKUP(D112,'AR PnL Mapping'!$C$3:$C$60,'AR PnL Mapping'!$B$3:$B$60,""),IF(OR(_xlpm.r="",_xlpm.r=0),"",_xlpm.r)) | D112: NET OPERATING INCOME | F112: =_xlfn.XLOOKUP($D112,'AR Historical Financials'!$C$8:$C$93,'AR Historical Financials'!E$8:E$93) -> 110425 | G112: =_xlfn.XLOOKUP($D112,'AR Historical Financials'!$C$8:$C$93,'AR Historical Financials'!F$8:F$93) -> 128635 | H112: =_xlfn.XLOOKUP($D112,'AR Historical Financials'!$C$8:$C$93,'AR Historical Financials'!G$8:G$93) -> 128564 | I112: =_xlfn.XLOOKUP($D112,'AR Historical Financials'!$C$8:$C$93,'AR Historical Financials'!H$8:H$93) -> 120208 | J112: =_xlfn.XLOOKUP($D112,'AR Historical Financials'!$C$8:$C$93,'AR Historical Financials'!I$8:I$93) -> 146294 | K112: =_xlfn.XLOOKUP($D112,'AR Historical Financials'!$C$8:$C$93,'AR Historical Financials'!J$8:J$93) -> 132565 | L112: =_xlfn.XLOOKUP($D112,'AR Historical Financials'!$C$8:$C$93,'AR Historical Financials'!K$8:K$93) -> 132911 | M112: =_xlfn.XLOOKUP($D112,'AR Historical Financials'!$C$8:$C$93,'AR Historical Financials'!L$8:L$93) -> 134889 | ... Q112: =_xlfn.XLOOKUP($D112,'AR Historical Financials'!$C$8:$C$93,'AR Historical Financials'!P$8:P$93) -> 146787 | S112: =IFERROR(SUMIFS($E112:$Q112,$E$5:$Q$5,">="&S$4,$E$5:$Q$5,"<="&S$5),0)*S$2 -> 1614832 | T112: =IFERROR(SUMIFS($E112:$Q112,$E$5:$Q$5,">="&T$4,$E$5:$Q$5,"<="&T$5),0)*T$2 -> 1696282 | U112: =IFERROR(SUMIFS($E112:$Q112,$E$5:$Q$5,">="&U$4,$E$5:$Q$5,"<="&U$5),0)*U$2 -> 1748728
B116: AL Rent | C116: Rent Revenue - AL | F116: =+SUMIFS(F$25:F$113,$B$25:$B$113,$C116) -> 120910 | G116: =+SUMIFS(G$25:G$113,$B$25:$B$113,$C116) -> 125160 | H116: =+SUMIFS(H$25:H$113,$B$25:$B$113,$C116) -> 124124 | I116: =+SUMIFS(I$25:I$113,$B$25:$B$113,$C116) -> 118673 | J116: =+SUMIFS(J$25:J$113,$B$25:$B$113,$C116) -> 123170 | K116: =+SUMIFS(K$25:K$113,$B$25:$B$113,$C116) -> 128565 | L116: =+SUMIFS(L$25:L$113,$B$25:$B$113,$C116) -> 129671 | M116: =+SUMIFS(M$25:M$113,$B$25:$B$113,$C116) -> 125562 | ... Q116: =+SUMIFS(Q$25:Q$113,$B$25:$B$113,$C116) -> 128925 | S116: =IFERROR(SUMIFS($E116:$Q116,$E$5:$Q$5,">="&S$4,$E$5:$Q$5,"<="&S$5),0)*S$2 -> 1506396 | T116: =IFERROR(SUMIFS($E116:$Q116,$E$5:$Q$5,">="&T$4,$E$5:$Q$5,"<="&T$5),0)*T$2 -> 1531588 | U116: =IFERROR(SUMIFS($E116:$Q116,$E$5:$Q$5,">="&U$4,$E$5:$Q$5,"<="&U$5),0)*U$2 -> 1541664
B117: IL Rent | C117: Rent Revenue - IL | F117: =+SUMIFS(F$25:F$113,$B$25:$B$113,$C117) -> 130152 | G117: =+SUMIFS(G$25:G$113,$B$25:$B$113,$C117) -> 130398 | H117: =+SUMIFS(H$25:H$113,$B$25:$B$113,$C117) -> 133507 | I117: =+SUMIFS(I$25:I$113,$B$25:$B$113,$C117) -> 132350 | J117: =+SUMIFS(J$25:J$113,$B$25:$B$113,$C117) -> 135400 | K117: =+SUMIFS(K$25:K$113,$B$25:$B$113,$C117) -> 135680 | L117: =+SUMIFS(L$25:L$113,$B$25:$B$113,$C117) -> 136760 | M117: =+SUMIFS(M$25:M$113,$B$25:$B$113,$C117) -> 133994 | ... Q117: =+SUMIFS(Q$25:Q$113,$B$25:$B$113,$C117) -> 140535 | S117: =IFERROR(SUMIFS($E117:$Q117,$E$5:$Q$5,">="&S$4,$E$5:$Q$5,"<="&S$5),0)*S$2 -> 1624031 | T117: =IFERROR(SUMIFS($E117:$Q117,$E$5:$Q$5,">="&T$4,$E$5:$Q$5,"<="&T$5),0)*T$2 -> 1653088 | U117: =IFERROR(SUMIFS($E117:$Q117,$E$5:$Q$5,">="&U$4,$E$5:$Q$5,"<="&U$5),0)*U$2 -> 1670908
B118: TC Rent | C118: Rent Revenue - TC | F118: =+SUMIFS(F$25:F$113,$B$25:$B$113,$C118) -> 0 | G118: =+SUMIFS(G$25:G$113,$B$25:$B$113,$C118) -> 0 | H118: =+SUMIFS(H$25:H$113,$B$25:$B$113,$C118) -> 0 | I118: =+SUMIFS(I$25:I$113,$B$25:$B$113,$C118) -> 0 | J118: =+SUMIFS(J$25:J$113,$B$25:$B$113,$C118) -> 0 | K118: =+SUMIFS(K$25:K$113,$B$25:$B$113,$C118) -> 0 | L118: =+SUMIFS(L$25:L$113,$B$25:$B$113,$C118) -> 0 | M118: =+SUMIFS(M$25:M$113,$B$25:$B$113,$C118) -> 0 | ... Q118: =+SUMIFS(Q$25:Q$113,$B$25:$B$113,$C118) -> 0 | S118: =IFERROR(SUMIFS($E118:$Q118,$E$5:$Q$5,">="&S$4,$E$5:$Q$5,"<="&S$5),0)*S$2 -> 0 | T118: =IFERROR(SUMIFS($E118:$Q118,$E$5:$Q$5,">="&T$4,$E$5:$Q$5,"<="&T$5),0)*T$2 -> 0 | U118: =IFERROR(SUMIFS($E118:$Q118,$E$5:$Q$5,">="&U$4,$E$5:$Q$5,"<="&U$5),0)*U$2 -> 0
B119: MC Rent | C119: Rent Revenue - MC | F119: =+SUMIFS(F$25:F$113,$B$25:$B$113,$C119) -> 86707 | G119: =+SUMIFS(G$25:G$113,$B$25:$B$113,$C119) -> 93912 | H119: =+SUMIFS(H$25:H$113,$B$25:$B$113,$C119) -> 93135 | I119: =+SUMIFS(I$25:I$113,$B$25:$B$113,$C119) -> 92846 | J119: =+SUMIFS(J$25:J$113,$B$25:$B$113,$C119) -> 101036 | K119: =+SUMIFS(K$25:K$113,$B$25:$B$113,$C119) -> 94072 | L119: =+SUMIFS(L$25:L$113,$B$25:$B$113,$C119) -> 94660 | M119: =+SUMIFS(M$25:M$113,$B$25:$B$113,$C119) -> 102463 | ... Q119: =+SUMIFS(Q$25:Q$113,$B$25:$B$113,$C119) -> 101595 | S119: =IFERROR(SUMIFS($E119:$Q119,$E$5:$Q$5,">="&S$4,$E$5:$Q$5,"<="&S$5),0)*S$2 -> 1155856 | T119: =IFERROR(SUMIFS($E119:$Q119,$E$5:$Q$5,">="&T$4,$E$5:$Q$5,"<="&T$5),0)*T$2 -> 1188296 | U119: =IFERROR(SUMIFS($E119:$Q119,$E$5:$Q$5,">="&U$4,$E$5:$Q$5,"<="&U$5),0)*U$2 -> 1181216
B120: Rent Concessions | C120: Rent Concessions | F120: =+SUMIFS(F$25:F$113,$B$25:$B$113,$C120) -> 0 | G120: =+SUMIFS(G$25:G$113,$B$25:$B$113,$C120) -> 0 | H120: =+SUMIFS(H$25:H$113,$B$25:$B$113,$C120) -> 0 | I120: =+SUMIFS(I$25:I$113,$B$25:$B$113,$C120) -> 0 | J120: =+SUMIFS(J$25:J$113,$B$25:$B$113,$C120) -> 0 | K120: =+SUMIFS(K$25:K$113,$B$25:$B$113,$C120) -> 0 | L120: =+SUMIFS(L$25:L$113,$B$25:$B$113,$C120) -> 0 | M120: =+SUMIFS(M$25:M$113,$B$25:$B$113,$C120) -> 0 | ... Q120: =+SUMIFS(Q$25:Q$113,$B$25:$B$113,$C120) -> 0 | S120: =IFERROR(SUMIFS($E120:$Q120,$E$5:$Q$5,">="&S$4,$E$5:$Q$5,"<="&S$5),0)*S$2 -> 0 | T120: =IFERROR(SUMIFS($E120:$Q120,$E$5:$Q$5,">="&T$4,$E$5:$Q$5,"<="&T$5),0)*T$2 -> 0 | U120: =IFERROR(SUMIFS($E120:$Q120,$E$5:$Q$5,">="&U$4,$E$5:$Q$5,"<="&U$5),0)*U$2 -> 0
B121: Other Revenue | C121: Other Revenue | F121: =+SUMIFS(F$25:F$113,$B$25:$B$113,$C121) -> 6094 | G121: =+SUMIFS(G$25:G$113,$B$25:$B$113,$C121) -> 5169 | H121: =+SUMIFS(H$25:H$113,$B$25:$B$113,$C121) -> 5035 | I121: =+SUMIFS(I$25:I$113,$B$25:$B$113,$C121) -> 5675 | J121: =+SUMIFS(J$25:J$113,$B$25:$B$113,$C121) -> 5730 | K121: =+SUMIFS(K$25:K$113,$B$25:$B$113,$C121) -> 5439 | L121: =+SUMIFS(L$25:L$113,$B$25:$B$113,$C121) -> 5568 | M121: =+SUMIFS(M$25:M$113,$B$25:$B$113,$C121) -> 5520 | ... Q121: =+SUMIFS(Q$25:Q$113,$B$25:$B$113,$C121) -> 5659 | S121: =IFERROR(SUMIFS($E121:$Q121,$E$5:$Q$5,">="&S$4,$E$5:$Q$5,"<="&S$5),0)*S$2 -> 66566 | T121: =IFERROR(SUMIFS($E121:$Q121,$E$5:$Q$5,">="&T$4,$E$5:$Q$5,"<="&T$5),0)*T$2 -> 66848 | U121: =IFERROR(SUMIFS($E121:$Q121,$E$5:$Q$5,">="&U$4,$E$5:$Q$5,"<="&U$5),0)*U$2 -> 68820
B122: Other Revenue | C122: Commercial Lease Revenue | F122: =+SUMIFS(F$25:F$113,$B$25:$B$113,$C122) -> 0 | G122: =+SUMIFS(G$25:G$113,$B$25:$B$113,$C122) -> 0 | H122: =+SUMIFS(H$25:H$113,$B$25:$B$113,$C122) -> 0 | I122: =+SUMIFS(I$25:I$113,$B$25:$B$113,$C122) -> 0 | J122: =+SUMIFS(J$25:J$113,$B$25:$B$113,$C122) -> 0 | K122: =+SUMIFS(K$25:K$113,$B$25:$B$113,$C122) -> 0 | L122: =+SUMIFS(L$25:L$113,$B$25:$B$113,$C122) -> 0 | M122: =+SUMIFS(M$25:M$113,$B$25:$B$113,$C122) -> 0 | ... Q122: =+SUMIFS(Q$25:Q$113,$B$25:$B$113,$C122) -> 0 | S122: =IFERROR(SUMIFS($E122:$Q122,$E$5:$Q$5,">="&S$4,$E$5:$Q$5,"<="&S$5),0)*S$2 -> 0 | T122: =IFERROR(SUMIFS($E122:$Q122,$E$5:$Q$5,">="&T$4,$E$5:$Q$5,"<="&T$5),0)*T$2 -> 0 | U122: =IFERROR(SUMIFS($E122:$Q122,$E$5:$Q$5,">="&U$4,$E$5:$Q$5,"<="&U$5),0)*U$2 -> 0
B123: Other Revenue | C123: Rent - Second Person | F123: =+SUMIFS(F$25:F$113,$B$25:$B$113,$C123) -> 7297 | G123: =+SUMIFS(G$25:G$113,$B$25:$B$113,$C123) -> 7396 | H123: =+SUMIFS(H$25:H$113,$B$25:$B$113,$C123) -> 7551 | I123: =+SUMIFS(I$25:I$113,$B$25:$B$113,$C123) -> 7493 | J123: =+SUMIFS(J$25:J$113,$B$25:$B$113,$C123) -> 7787 | K123: =+SUMIFS(K$25:K$113,$B$25:$B$113,$C123) -> 7905 | L123: =+SUMIFS(L$25:L$113,$B$25:$B$113,$C123) -> 7847 | M123: =+SUMIFS(M$25:M$113,$B$25:$B$113,$C123) -> 7539 | ... Q123: =+SUMIFS(Q$25:Q$113,$B$25:$B$113,$C123) -> 7960 | S123: =IFERROR(SUMIFS($E123:$Q123,$E$5:$Q$5,">="&S$4,$E$5:$Q$5,"<="&S$5),0)*S$2 -> 92194 | T123: =IFERROR(SUMIFS($E123:$Q123,$E$5:$Q$5,">="&T$4,$E$5:$Q$5,"<="&T$5),0)*T$2 -> 93530 | U123: =IFERROR(SUMIFS($E123:$Q123,$E$5:$Q$5,">="&U$4,$E$5:$Q$5,"<="&U$5),0)*U$2 -> 94964
...

Sheet Census
A1: Aster Ridge Senior Living (DEMO) -- Occupancy Report
A2: Jul 2024 - Jun 2026
A3: SYNTHETIC DEMO DATA -- NOT A REAL COMMUNITY. All figures fabricated for demonstration/testing purposes only.
A6: Month | B6: 45504 | C6: 45535 | D6: 45565 | E6: 45596 | F6: 45626 | G6: 45657 | H6: 45688 | I6: 45716 | J6: 45747 | K6: 45777 | L6: 45808 | M6: 45838 | N6: 45869 | O6: 45900 | P6: 45930 | Q6: 45961 | R6: 45991 | S6: 46022 | T6: 46053 | U6: 46081 | V6: 46112 | W6: 46142 | X6: 46173 | Y6: 46203
A7: Capacity
A8: IL | B8: 40 | C8: 40 | D8: 40 | E8: 40 | F8: 40 | G8: 40 | H8: 40 | I8: 40 | J8: 40 | K8: 40 | L8: 40 | M8: 40 | N8: 40 | O8: 40 | P8: 40 | Q8: 40 | R8: 40 | S8: 40 | T8: 40 | U8: 40 | V8: 40 | W8: 40 | X8: 40 | Y8: 40
A9: AL | B9: 30 | C9: 30 | D9: 30 | E9: 30 | F9: 30 | G9: 30 | H9: 30 | I9: 30 | J9: 30 | K9: 30 | L9: 30 | M9: 30 | N9: 30 | O9: 30 | P9: 30 | Q9: 30 | R9: 30 | S9: 30 | T9: 30 | U9: 30 | V9: 30 | W9: 30 | X9: 30 | Y9: 30
A10: MC | B10: 14 | C10: 14 | D10: 14 | E10: 14 | F10: 14 | G10: 14 | H10: 14 | I10: 14 | J10: 14 | K10: 14 | L10: 14 | M10: 14 | N10: 14 | O10: 14 | P10: 14 | Q10: 14 | R10: 14 | S10: 14 | T10: 14 | U10: 14 | V10: 14 | W10: 14 | X10: 14 | Y10: 14
A11: Total | B11: 84 | C11: 84 | D11: 84 | E11: 84 | F11: 84 | G11: 84 | H11: 84 | I11: 84 | J11: 84 | K11: 84 | L11: 84 | M11: 84 | N11: 84 | O11: 84 | P11: 84 | Q11: 84 | R11: 84 | S11: 84 | T11: 84 | U11: 84 | V11: 84 | W11: 84 | X11: 84 | Y11: 84
A13: Occupied (Month-End)
A14: IL | B14: 32 | C14: 32 | D14: 32 | E14: 33 | F14: 33 | G14: 33 | H14: 33 | I14: 33 | J14: 33 | K14: 34 | L14: 34 | M14: 34 | N14: 34 | O14: 34 | P14: 35 | Q14: 35 | R14: 36 | S14: 36 | T14: 36 | U14: 35 | V14: 36 | W14: 36 | X14: 37 | Y14: 37
A15: AL | B15: 25 | C15: 25 | D15: 25 | E15: 25 | F15: 25 | G15: 25 | H15: 26 | I15: 26 | J15: 26 | K15: 26 | L15: 26 | M15: 26 | N15: 26 | O15: 27 | P15: 27 | Q15: 26 | R15: 27 | S15: 28 | T15: 28 | U15: 27 | V15: 27 | W15: 28 | X15: 28 | Y15: 28
A16: MC | B16: 10 | C16: 10 | D16: 10 | E16: 10 | F16: 10 | G16: 10 | H16: 11 | I16: 11 | J16: 11 | K16: 11 | L16: 11 | M16: 11 | N16: 11 | O16: 12 | P16: 12 | Q16: 12 | R16: 13 | S16: 12 | T16: 12 | U16: 13 | V16: 13 | W16: 12 | X16: 13 | Y16: 13
A17: Total | B17: 67 | C17: 67 | D17: 67 | E17: 68 | F17: 68 | G17: 68 | H17: 70 | I17: 70 | J17: 70 | K17: 71 | L17: 71 | M17: 71 | N17: 71 | O17: 73 | P17: 74 | Q17: 73 | R17: 76 | S17: 76 | T17: 76 | U17: 75 | V17: 76 | W17: 76 | X17: 78 | Y17: 78
B20: Output | E20: 45869 | F20: 45900 | G20: 45930 | H20: 45961 | I20: 45991 | J20: 46022 | K20: 46053 | L20: 46081 | M20: 46112 | N20: 46142 | O20: 46173 | P20: 46203
C22: Days | E22: =DAY(E20) -> 31 | F22: =DAY(F20) -> 31 | G22: =DAY(G20) -> 30 | H22: =DAY(H20) -> 31 | I22: =DAY(I20) -> 30 | J22: =DAY(J20) -> 31 | K22: =DAY(K20) -> 31 | L22: =DAY(L20) -> 28 | ... P22: =DAY(P20) -> 30
B24: Capacity | C24: IL | E24: =N8 -> 40 | F24: =O8 -> 40 | G24: =P8 -> 40 | H24: =Q8 -> 40 | I24: =R8 -> 40 | J24: =S8 -> 40 | K24: =T8 -> 40 | L24: =U8 -> 40 | ... P24: =Y8 -> 40
B25: Capacity | C25: AL | E25: =N9 -> 30 | F25: =O9 -> 30 | G25: =P9 -> 30 | H25: =Q9 -> 30 | I25: =R9 -> 30 | J25: =S9 -> 30 | K25: =T9 -> 30 | L25: =U9 -> 30 | ... P25: =Y9 -> 30
B26: Capacity | C26: MC | E26: =N10 -> 14 | F26: =O10 -> 14 | G26: =P10 -> 14 | H26: =Q10 -> 14 | I26: =R10 -> 14 | J26: =S10 -> 14 | K26: =T10 -> 14 | L26: =U10 -> 14 | ... P26: =Y10 -> 14
B27: Capacity | C27: Total | E27: =SUM(E24:E26) -> 84 | F27: =SUM(F24:F26) -> 84 | G27: =SUM(G24:G26) -> 84 | H27: =SUM(H24:H26) -> 84 | I27: =SUM(I24:I26) -> 84 | J27: =SUM(J24:J26) -> 84 | K27: =SUM(K24:K26) -> 84 | L27: =SUM(L24:L26) -> 84 | ... P27: =SUM(P24:P26) -> 84
B29: Occupied | C29: IL | E29: =N14 -> 34 | F29: =O14 -> 34 | G29: =P14 -> 35 | H29: =Q14 -> 35 | I29: =R14 -> 36 | J29: =S14 -> 36 | K29: =T14 -> 36 | L29: =U14 -> 35 | ... P29: =Y14 -> 37
B30: Occupied | C30: AL | E30: =N15 -> 26 | F30: =O15 -> 27 | G30: =P15 -> 27 | H30: =Q15 -> 26 | I30: =R15 -> 27 | J30: =S15 -> 28 | K30: =T15 -> 28 | L30: =U15 -> 27 | ... P30: =Y15 -> 28
B31: Occupied | C31: MC | E31: =N16 -> 11 | F31: =O16 -> 12 | G31: =P16 -> 12 | H31: =Q16 -> 12 | I31: =R16 -> 13 | J31: =S16 -> 12 | K31: =T16 -> 12 | L31: =U16 -> 13 | ... P31: =Y16 -> 13
B32: Occupied | C32: Total | E32: =SUM(E29:E31) -> 71 | F32: =SUM(F29:F31) -> 73 | G32: =SUM(G29:G31) -> 74 | H32: =SUM(H29:H31) -> 73 | I32: =SUM(I29:I31) -> 76 | J32: =SUM(J29:J31) -> 76 | K32: =SUM(K29:K31) -> 76 | L32: =SUM(L29:L31) -> 75 | ... P32: =SUM(P29:P31) -> 78
B34: Avg Occ % | C34: IL | E34: =E29/E24 -> 0.85 | F34: =F29/F24 -> 0.85 | G34: =G29/G24 -> 0.875 | H34: =H29/H24 -> 0.875 | I34: =I29/I24 -> 0.9 | J34: =J29/J24 -> 0.9 | K34: =K29/K24 -> 0.9 | L34: =L29/L24 -> 0.875 | ... P34: =P29/P24 -> 0.925
B35: Avg Occ % | C35: AL | E35: =E30/E25 -> 0.86666667 | F35: =F30/F25 -> 0.9 | G35: =G30/G25 -> 0.9 | H35: =H30/H25 -> 0.86666667 | I35: =I30/I25 -> 0.9 | J35: =J30/J25 -> 0.93333333 | K35: =K30/K25 -> 0.93333333 | L35: =L30/L25 -> 0.9 | ... P35: =P30/P25 -> 0.93333333
B36: Avg Occ % | C36: MC | E36: =E31/E26 -> 0.78571429 | F36: =F31/F26 -> 0.85714286 | G36: =G31/G26 -> 0.85714286 | H36: =H31/H26 -> 0.85714286 | I36: =I31/I26 -> 0.92857143 | J36: =J31/J26 -> 0.85714286 | K36: =K31/K26 -> 0.85714286 | L36: =L31/L26 -> 0.92857143 | ... P36: =P31/P26 -> 0.92857143

Sheet AR PnL Mapping
A2: Check | C2: Tag | D2: Questions & Comments | E2: List of Tags
C3: REVENUE | E3: Rent Revenue - AL
A4: =IF(COUNTIF($E:$E,B4),"Yes","No") -> Yes | B4: Rent Revenue - IL | C4: 4010 - Rent Income - IL | E4: Rent Revenue - IL
A5: =IF(COUNTIF($E:$E,B5),"Yes","No") -> Yes | B5: Rent Revenue - AL | C5: 4020 - Rent Income - AL | E5: Rent Revenue - TC
A6: =IF(COUNTIF($E:$E,B6),"Yes","No") -> Yes | B6: Rent Revenue - MC | C6: 4030 - Rent Income - MC | E6: Rent Revenue - MC
C7: TOTAL RENT REVENUE | E7: Rent Concessions
A8: =IF(COUNTIF($E:$E,B8),"Yes","No") -> Yes | B8: Care Revenue - AL | C8: 4110 - Care Level Income - AL | E8: Other Revenue
A9: =IF(COUNTIF($E:$E,B9),"Yes","No") -> Yes | B9: Care Revenue - MC | C9: 4120 - Care Level Income - MC | E9: Commercial Lease Revenue
C10: TOTAL CARE REVENUE | E10: Rent - Second Person
A11: =IF(COUNTIF($E:$E,B11),"Yes","No") -> Yes | B11: Rent - Second Person | C11: 4210 - Second Person Fees | E11: Care Revenue - AL
A12: =IF(COUNTIF($E:$E,B12),"Yes","No") -> Yes | B12: Community Fees | C12: 4310 - Community Fees | E12: Care Revenue - MC
A13: =IF(COUNTIF($E:$E,B13),"Yes","No") -> Yes | B13: Other Revenue | C13: 4410 - Other Resident Income | E13: Community Fees
A14: =IF(COUNTIF($E:$E,B14),"Yes","No") -> Yes | B14: Other Revenue | C14: 4510 - Guest Meals & Ancillary | E14: Wages - Admin
C15: TOTAL OTHER REVENUE | E15: Wages - Culinary
C16: TOTAL REVENUE | E16: Wages - Direct Care
C17: EXPENSES | E17: Wages - Activities
A18: =IF(COUNTIF($E:$E,B18),"Yes","No") -> Yes | B18: Wages - Culinary | C18: 6110 - Dining Wages | E18: Wages - Housekeeping
A19: =IF(COUNTIF($E:$E,B19),"Yes","No") -> Yes | B19: Wages - Culinary | C19: 6120 - Dining Director | E19: Wages - Maintenance
A20: =IF(COUNTIF($E:$E,B20),"Yes","No") -> Yes | B20: Raw Food | C20: 7010 - Raw Food | E20: Wages - Marketing
A21: =IF(COUNTIF($E:$E,B21),"Yes","No") -> Yes | B21: Culinary | C21: 7020 - Dining Supplies | E21: Bonuses - Marketing
C22: TOTAL CULINARY EXPENSES | E22: Bonuses - Admin
A23: =IF(COUNTIF($E:$E,B23),"Yes","No") -> Yes | B23: Wages - Activities | C23: 6410 - Activities Wages | E23: Contract Labor - Maintenance
C24: TOTAL ACTIVITIES EXPENSES | E24: Contract Labor - Marketing
A25: =IF(COUNTIF($E:$E,B25),"Yes","No") -> Yes | B25: Wages - Direct Care | C25: 6010 - Caregiver Wages | E25: Contract Labor - Culinary
A26: =IF(COUNTIF($E:$E,B26),"Yes","No") -> Yes | B26: Wages - Direct Care | C26: 6020 - Med Tech Wages | E26: Contract Labor - Activities
A27: =IF(COUNTIF($E:$E,B27),"Yes","No") -> Yes | B27: Wages - Direct Care | C27: 6030 - Wellness Director | E27: Contract Labor - Admin
A28: =IF(COUNTIF($E:$E,B28),"Yes","No") -> Yes | B28: Direct Care | C28: 7210 - Care Supplies | E28: Contract Labor - Direct Care
C29: TOTAL WELLNESS - NURSING EXPENSES | E29: Contract Labor - Housekeeping
A30: =IF(COUNTIF($E:$E,B30),"Yes","No") -> Yes | B30: Wages - Maintenance | C30: 6310 - Maintenance Wages | E30: Benefits - Activities
A31: =IF(COUNTIF($E:$E,B31),"Yes","No") -> Yes | B31: Maintenance | C31: 7610 - Repairs & Maintenance | E31: Benefits - Culinary
C32: TOTAL MAINTENANCE EXPENSES | E32: Benefits - Direct Care
A33: =IF(COUNTIF($E:$E,B33),"Yes","No") -> Yes | B33: Utilities | C33: 7510 - Electricity | E33: Benefits - Marketing
A34: =IF(COUNTIF($E:$E,B34),"Yes","No") -> Yes | B34: Utilities | C34: 7520 - Gas | E34: Benefits - Housekeeping
A35: =IF(COUNTIF($E:$E,B35),"Yes","No") -> Yes | B35: Utilities | C35: 7530 - Water/Sewer | E35: Benefits - Maintenance
A36: =IF(COUNTIF($E:$E,B36),"Yes","No") -> Yes | B36: Utilities | C36: 7540 - Trash | E36: Benefits - Admin
C37: TOTAL UTILITIES EXPENSES | E37: Raw Food
A38: =IF(COUNTIF($E:$E,B38),"Yes","No") -> Yes | B38: Wages - Housekeeping | C38: 6210 - Housekeeping Wages | E38: Culinary
A39: =IF(COUNTIF($E:$E,B39),"Yes","No") -> Yes | B39: Housekeeping | C39: 7110 - Housekeeping Supplies | E39: Activities
C40: TOTAL HOUSEKEEPING EXPENSE | E40: Direct Care
A41: =IF(COUNTIF($E:$E,B41),"Yes","No") -> Yes | B41: Wages - Marketing | C41: 6630 - Sales & Marketing Wages | E41: COGS
...

Sheet AR Historical Financials
C2: Aster Ridge Senior Living (DEMO)
C3: Statement (12 months)
C4: Period = Jul 2025 - Jun 2026
C5: Book = Accrual ; Tree = wlf_cf
A6: x | C6: REVENUE | E6: 45869 | F6: 45900 | G6: 45930 | H6: 45961 | I6: 45991 | J6: 46022 | K6: 46053 | L6: 46081 | M6: 46112 | N6: 46142 | O6: 46173 | P6: 46203 | Q6: Total
C8: =IF(S8="",T8,S8&" - "&T8) -> 4010 - Rent Income - IL | E8: 130152 | F8: 130398 | G8: 133507 | H8: 132350 | I8: 135400 | J8: 135680 | K8: 136760 | L8: 133994 | M8: 138063 | N8: 137300 | O8: 139892 | P8: 140535 | Q8: =SUM(E8:P8) -> 1624031 | S8: 4010 | T8: Rent Income - IL
C9: =IF(S9="",T9,S9&" - "&T9) -> 4020 - Rent Income - AL | E9: 120910 | F9: 125160 | G9: 124124 | H9: 118673 | I9: 123170 | J9: 128565 | K9: 129671 | L9: 125562 | M9: 125145 | N9: 128700 | O9: 127791 | P9: 128925 | Q9: =SUM(E9:P9) -> 1506396 | S9: 4020 | T9: Rent Income - AL
C10: =IF(S10="",T10,S10&" - "&T10) -> 4030 - Rent Income - MC | E10: 86707 | F10: 93912 | G10: 93135 | H10: 92846 | I10: 101036 | J10: 94072 | K10: 94660 | L10: 102463 | M10: 101721 | N10: 93124 | O10: 100585 | P10: 101595 | Q10: =SUM(E10:P10) -> 1155856 | S10: 4030 | T10: Rent Income - MC
A12: x | C12: TOTAL RENT REVENUE | E12: =E8+E9+E10 -> 337769 | F12: =F8+F9+F10 -> 349470 | G12: =G8+G9+G10 -> 350766 | H12: =H8+H9+H10 -> 343869 | I12: =I8+I9+I10 -> 359606 | J12: =J8+J9+J10 -> 358317 | K12: =K8+K9+K10 -> 361091 | L12: =L8+L9+L10 -> 362019 | ... Q12: =Q8+Q9+Q10 -> 4286283
C14: =IF(S14="",T14,S14&" - "&T14) -> 4110 - Care Level Income - AL | E14: 25794 | F14: 26554 | G14: 26411 | H14: 25486 | I14: 26677 | J14: 27880 | K14: 27928 | L14: 26782 | M14: 26550 | N14: 27389 | O14: 27449 | P14: 27660 | Q14: =SUM(E14:P14) -> 322560 | S14: 4110 | T14: Care Level Income - AL
C15: =IF(S15="",T15,S15&" - "&T15) -> 4120 - Care Level Income - MC | E15: 15207 | F15: 16471 | G15: 16462 | H15: 16569 | I15: 18104 | J15: 16781 | K15: 16726 | L15: 17969 | M15: 17842 | N15: 16463 | O15: 17953 | P15: 18000 | Q15: =SUM(E15:P15) -> 204547 | S15: 4120 | T15: Care Level Income - MC
A17: x | C17: TOTAL CARE REVENUE | E17: =E14+E15 -> 41001 | F17: =F14+F15 -> 43025 | G17: =G14+G15 -> 42873 | H17: =H14+H15 -> 42055 | I17: =I14+I15 -> 44781 | J17: =J14+J15 -> 44661 | K17: =K14+K15 -> 44654 | L17: =L14+L15 -> 44751 | ... Q17: =Q14+Q15 -> 527107
C19: =IF(S19="",T19,S19&" - "&T19) -> 4210 - Second Person Fees | E19: 7297 | F19: 7396 | G19: 7551 | H19: 7493 | I19: 7787 | J19: 7905 | K19: 7847 | L19: 7539 | M19: 7638 | N19: 7795 | O19: 7986 | P19: 7960 | Q19: =SUM(E19:P19) -> 92194 | S19: 4210 | T19: Second Person Fees
C20: =IF(S20="",T20,S20&" - "&T20) -> 4310 - Community Fees | E20: 4087 | F20: 9901 | G20: 5616 | H20: 3000 | I20: 13391 | J20: 3969 | K20: 3000 | L20: 3000 | M20: 6430 | N20: 4092 | O20: 9873 | P20: 3000 | Q20: =SUM(E20:P20) -> 69359 | S20: 4310 | T20: Community Fees
C21: =IF(S21="",T21,S21&" - "&T21) -> 4410 - Other Resident Income | E21: 3577 | F21: 3254 | G21: 2852 | H21: 2960 | I21: 3420 | J21: 3557 | K21: 3171 | L21: 2827 | M21: 3029 | N21: 3481 | O21: 3521 | P21: 3091 | Q21: =SUM(E21:P21) -> 38740 | S21: 4410 | T21: Other Resident Income
C22: =IF(S22="",T22,S22&" - "&T22) -> 4510 - Guest Meals & Ancillary | E22: 2517 | F22: 1915 | G22: 2183 | H22: 2715 | I22: 2310 | J22: 1882 | K22: 2397 | L22: 2693 | M22: 2102 | N22: 1958 | O22: 2586 | P22: 2568 | Q22: =SUM(E22:P22) -> 27826 | S22: 4510 | T22: Guest Meals & Ancillary
A24: x | C24: TOTAL OTHER REVENUE | E24: =E19+E20+E21+E22 -> 17478 | F24: =F19+F20+F21+F22 -> 22466 | G24: =G19+G20+G21+G22 -> 18202 | H24: =H19+H20+H21+H22 -> 16168 | I24: =I19+I20+I21+I22 -> 26908 | J24: =J19+J20+J21+J22 -> 17313 | K24: =K19+K20+K21+K22 -> 16415 | L24: =L19+L20+L21+L22 -> 16059 | ... Q24: =Q19+Q20+Q21+Q22 -> 228119
A26: x | C26: TOTAL REVENUE | E26: =E12+E17+E24 -> 396248 | F26: =F12+F17+F24 -> 414961 | G26: =G12+G17+G24 -> 411841 | H26: =H12+H17+H24 -> 402092 | I26: =I12+I17+I24 -> 431295 | J26: =J12+J17+J24 -> 420291 | K26: =K12+K17+K24 -> 422160 | L26: =L12+L17+L24 -> 422829 | ... Q26: =Q12+Q17+Q24 -> 5041509
A28: x | C28: EXPENSES
C30: =IF(S30="",T30,S30&" - "&T30) -> 6110 - Dining Wages | E30: 24823 | F30: 24567 | G30: 24610 | H30: 24904 | I30: 25129 | J30: 25038 | K30: 24731 | L30: 24543 | M30: 24680 | N30: 24992 | O30: 25137 | P30: 24958 | Q30: =SUM(E30:P30) -> 298112 | S30: 6110 | T30: Dining Wages
C31: =IF(S31="",T31,S31&" - "&T31) -> 6120 - Dining Director | E31: 4749 | F31: 4728 | G31: 4768 | H31: 4826 | I31: 4838 | J31: 4791 | K31: 4736 | L31: 4734 | M31: 4786 | N31: 4836 | O31: 4829 | P31: 4773 | Q31: =SUM(E31:P31) -> 57394 | S31: 6120 | T31: Dining Director
C32: =IF(S32="",T32,S32&" - "&T32) -> 7010 - Raw Food | E32: 14219 | F32: 14256 | G32: 14128 | H32: 13913 | I32: 13740 | J32: 13716 | K32: 13854 | L32: 14071 | M32: 14235 | N32: 14247 | O32: 14099 | P32: 13882 | Q32: =SUM(E32:P32) -> 168360 | S32: 7010 | T32: Raw Food
C33: =IF(S33="",T33,S33&" - "&T33) -> 7020 - Dining Supplies | E33: 2252 | F33: 2234 | G33: 2193 | H33: 2165 | I33: 2177 | J33: 2217 | K33: 2249 | L33: 2243 | M33: 2205 | N33: 2169 | O33: 2169 | P33: 2205 | Q33: =SUM(E33:P33) -> 26478 | S33: 7020 | T33: Dining Supplies
A35: x | C35: TOTAL CULINARY EXPENSES | E35: =E30+E31+E32+E33 -> 46043 | F35: =F30+F31+F32+F33 -> 45785 | G35: =G30+G31+G32+G33 -> 45699 | H35: =H30+H31+H32+H33 -> 45808 | I35: =I30+I31+I32+I33 -> 45884 | J35: =J30+J31+J32+J33 -> 45762 | K35: =K30+K31+K32+K33 -> 45570 | L35: =L30+L31+L32+L33 -> 45591 | ... Q35: =Q30+Q31+Q32+Q33 -> 550344
C37: =IF(S37="",T37,S37&" - "&T37) -> 6410 - Activities Wages | E37: 6209 | F37: 6286 | G37: 6331 | H37: 6294 | I37: 6215 | J37: 6181 | K37: 6229 | L37: 6306 | M37: 6328 | N37: 6271 | O37: 6198 | P37: 6187 | Q37: =SUM(E37:P37) -> 75035 | S37: 6410 | T37: Activities Wages
A39: x | C39: TOTAL ACTIVITIES EXPENSES | E39: =E37 -> 6209 | F39: =F37 -> 6286 | G39: =G37 -> 6331 | H39: =H37 -> 6294 | I39: =I37 -> 6215 | J39: =J37 -> 6181 | K39: =K37 -> 6229 | L39: =L37 -> 6306 | ... Q39: =Q37 -> 75035
C41: =IF(S41="",T41,S41&" - "&T41) -> 6010 - Caregiver Wages | E41: 45613 | F41: 45404 | G41: 44841 | H41: 44539 | I41: 44829 | J41: 45393 | K41: 45615 | L41: 45253 | M41: 44701 | N41: 44564 | O41: 44990 | P41: 45515 | Q41: =SUM(E41:P41) -> 541257 | S41: 6010 | T41: Caregiver Wages
C42: =IF(S42="",T42,S42&" - "&T42) -> 6020 - Med Tech Wages | E42: 17206 | F42: 17028 | G42: 16842 | H42: 16850 | I42: 17044 | J42: 17212 | K42: 17170 | L42: 16964 | M42: 16820 | N42: 16894 | O42: 17106 | P42: 17224 | Q42: =SUM(E42:P42) -> 204360 | S42: 6020 | T42: Med Tech Wages
C43: =IF(S43="",T43,S43&" - "&T43) -> 6030 - Wellness Director | E43: 5554 | F43: 5485 | G43: 5454 | H43: 5495 | I43: 5564 | J43: 5584 | K43: 5535 | L43: 5469 | M43: 5459 | N43: 5516 | O43: 5577 | P43: 5576 | Q43: =SUM(E43:P43) -> 66268 | S43: 6030 | T43: Wellness Director
C44: =IF(S44="",T44,S44&" - "&T44) -> 7210 - Care Supplies | E44: 3340 | F44: 3258 | G44: 3265 | H44: 3350 | I44: 3372 | J44: 3294 | K44: 3246 | L44: 3308 | M44: 3376 | N44: 3338 | O44: 3257 | P44: 3267 | Q44: =SUM(E44:P44) -> 39671 | S44: 7210 | T44: Care Supplies
A46: x | C46: TOTAL WELLNESS - NURSING EXPENSES | E46: =E41+E42+E43+E44 -> 71713 | F46: =F41+F42+F43+F44 -> 71175 | G46: =G41+G42+G43+G44 -> 70402 | H46: =H41+H42+H43+H44 -> 70234 | I46: =I41+I42+I43+I44 -> 70809 | J46: =J41+J42+J43+J44 -> 71483 | K46: =K41+K42+K43+K44 -> 71566 | L46: =L41+L42+L43+L44 -> 70994 | ... Q46: =Q41+Q42+Q43+Q44 -> 851556
C48: =IF(S48="",T48,S48&" - "&T48) -> 6310 - Maintenance Wages | E48: 8912 | F48: 8996 | G48: 9102 | H48: 9114 | I48: 9019 | J48: 8921 | K48: 8927 | L48: 9030 | M48: 9118 | N48: 9094 | O48: 8985 | P48: 8910 | Q48: =SUM(E48:P48) -> 108128 | S48: 6310 | T48: Maintenance Wages
C49: =IF(S49="",T49,S49&" - "&T49) -> 7610 - Repairs & Maintenance | E49: 6661 | F49: 6442 | G49: 6360 | H49: 6478 | I49: 6707 | J49: 6873 | K49: 6850 | L49: 6657 | M49: 6439 | N49: 6360 | O49: 6482 | P49: 6711 | Q49: =SUM(E49:P49) -> 79020 | S49: 7610 | T49: Repairs & Maintenance
A51: x | C51: TOTAL MAINTENANCE EXPENSES | E51: =E48+E49 -> 15573 | F51: =F48+F49 -> 15438 | G51: =G48+G49 -> 15462 | H51: =H48+H49 -> 15592 | I51: =I48+I49 -> 15726 | J51: =J48+J49 -> 15794 | K51: =K48+K49 -> 15777 | L51: =L48+L49 -> 15687 | ... Q51: =Q48+Q49 -> 187148
C53: =IF(S53="",T53,S53&" - "&T53) -> 7510 - Electricity | E53: 11592 | F53: 12075 | G53: 10143 | H53: 8694 | I53: 8694 | J53: 10143 | K53: 11109 | L53: 10626 | M53: 9177 | N53: 8211 | O53: 8694 | P53: 10626 | Q53: =SUM(E53:P53) -> 119784 | S53: 7510 | T53: Electricity
C54: =IF(S54="",T54,S54&" - "&T54) -> 7520 - Gas | E54: 1573 | F54: 1573 | G54: 1923 | H54: 2972 | I54: 4370 | J54: 5419 | K54: 5594 | L54: 5244 | M54: 4195 | N54: 2972 | O54: 2098 | P54: 1748 | Q54: =SUM(E54:P54) -> 39681 | S54: 7520 | T54: Gas
C55: =IF(S55="",T55,S55&" - "&T55) -> 7530 - Water/Sewer | E55: 4126 | F55: 4126 | G55: 3767 | H55: 3588 | I55: 3409 | J55: 3409 | K55: 3409 | L55: 3409 | M55: 3588 | N55: 3588 | O55: 3767 | P55: 4126 | Q55: =SUM(E55:P55) -> 44312 | S55: 7530 | T55: Water/Sewer
C56: =IF(S56="",T56,S56&" - "&T56) -> 7540 - Trash | E56: 1564 | F56: 1564 | G56: 1564 | H56: 1564 | I56: 1564 | J56: 1564 | K56: 1564 | L56: 1564 | M56: 1564 | N56: 1564 | O56: 1564 | P56: 1564 | Q56: =SUM(E56:P56) -> 18768 | S56: 7540 | T56: Trash
A58: x | C58: TOTAL UTILITIES EXPENSES | E58: =E53+E54+E55+E56 -> 18855 | F58: =F53+F54+F55+F56 -> 19338 | G58: =G53+G54+G55+G56 -> 17397 | H58: =H53+H54+H55+H56 -> 16818 | I58: =I53+I54+I55+I56 -> 18037 | J58: =J53+J54+J55+J56 -> 20535 | K58: =K53+K54+K55+K56 -> 21676 | L58: =L53+L54+L55+L56 -> 20843 | ... Q58: =Q53+Q54+Q55+Q56 -> 222545
C60: =IF(S60="",T60,S60&" - "&T60) -> 6210 - Housekeeping Wages | E60: 12278 | F60: 12315 | G60: 12466 | H60: 12567 | I60: 12507 | J60: 12352 | K60: 12271 | L60: 12353 | M60: 12508 | N60: 12567 | O60: 12465 | P60: 12314 | Q60: =SUM(E60:P60) -> 148963 | S60: 6210 | T60: Housekeeping Wages
...

Sheet AR Unformatted HF
A1: Aster Ridge Senior Living (DEMO)
A2: T12 Income Statement -- Jul 2025 through Jun 2026
A3: SYNTHETIC DEMO DATA -- NOT A REAL COMMUNITY. All figures fabricated for demonstration/testing purposes only.
A5: Acct | B5: Description | C5: 45869 | D5: 45900 | E5: 45930 | F5: 45961 | G5: 45991 | H5: 46022 | I5: 46053 | J5: 46081 | K5: 46112 | L5: 46142 | M5: 46173 | N5: 46203 | O5: Total
B6: REVENUE
A7: 4010 | B7: Rent Income - IL | C7: 130152 | D7: 130398 | E7: 133507 | F7: 132350 | G7: 135400 | H7: 135680 | I7: 136760 | J7: 133994 | K7: 138063 | L7: 137300 | M7: 139892 | N7: 140535 | O7: 1624031
A8: 4020 | B8: Rent Income - AL | C8: 120910 | D8: 125160 | E8: 124124 | F8: 118673 | G8: 123170 | H8: 128565 | I8: 129671 | J8: 125562 | K8: 125145 | L8: 128700 | M8: 127791 | N8: 128925 | O8: 1506396
A9: 4030 | B9: Rent Income - MC | C9: 86707 | D9: 93912 | E9: 93135 | F9: 92846 | G9: 101036 | H9: 94072 | I9: 94660 | J9: 102463 | K9: 101721 | L9: 93124 | M9: 100585 | N9: 101595 | O9: 1155856
A10: 4110 | B10: Care Level Income - AL | C10: 25794 | D10: 26554 | E10: 26411 | F10: 25486 | G10: 26677 | H10: 27880 | I10: 27928 | J10: 26782 | K10: 26550 | L10: 27389 | M10: 27449 | N10: 27660 | O10: 322560
A11: 4120 | B11: Care Level Income - MC | C11: 15207 | D11: 16471 | E11: 16462 | F11: 16569 | G11: 18104 | H11: 16781 | I11: 16726 | J11: 17969 | K11: 17842 | L11: 16463 | M11: 17953 | N11: 18000 | O11: 204547
A12: 4210 | B12: Second Person Fees | C12: 7297 | D12: 7396 | E12: 7551 | F12: 7493 | G12: 7787 | H12: 7905 | I12: 7847 | J12: 7539 | K12: 7638 | L12: 7795 | M12: 7986 | N12: 7960 | O12: 92194
A13: 4310 | B13: Community Fees | C13: 4087 | D13: 9901 | E13: 5616 | F13: 3000 | G13: 13391 | H13: 3969 | I13: 3000 | J13: 3000 | K13: 6430 | L13: 4092 | M13: 9873 | N13: 3000 | O13: 69359
A14: 4410 | B14: Other Resident Income | C14: 3577 | D14: 3254 | E14: 2852 | F14: 2960 | G14: 3420 | H14: 3557 | I14: 3171 | J14: 2827 | K14: 3029 | L14: 3481 | M14: 3521 | N14: 3091 | O14: 38740
A15: 4510 | B15: Guest Meals & Ancillary | C15: 2517 | D15: 1915 | E15: 2183 | F15: 2715 | G15: 2310 | H15: 1882 | I15: 2397 | J15: 2693 | K15: 2102 | L15: 1958 | M15: 2586 | N15: 2568 | O15: 27826
B16: TOTAL REVENUE | C16: 396248 | D16: 414961 | E16: 411841 | F16: 402092 | G16: 431295 | H16: 420291 | I16: 422160 | J16: 422829 | K16: 428520 | L16: 420302 | M16: 437636 | N16: 433334 | O16: 5041509
B18: OPERATING EXPENSES
A19: 6010 | B19: Caregiver Wages | C19: 45613 | D19: 45404 | E19: 44841 | F19: 44539 | G19: 44829 | H19: 45393 | I19: 45615 | J19: 45253 | K19: 44701 | L19: 44564 | M19: 44990 | N19: 45515 | O19: 541257
A20: 6020 | B20: Med Tech Wages | C20: 17206 | D20: 17028 | E20: 16842 | F20: 16850 | G20: 17044 | H20: 17212 | I20: 17170 | J20: 16964 | K20: 16820 | L20: 16894 | M20: 17106 | N20: 17224 | O20: 204360
A21: 6030 | B21: Wellness Director | C21: 5554 | D21: 5485 | E21: 5454 | F21: 5495 | G21: 5564 | H21: 5584 | I21: 5535 | J21: 5469 | K21: 5459 | L21: 5516 | M21: 5577 | N21: 5576 | O21: 66268
A22: 6110 | B22: Dining Wages | C22: 24823 | D22: 24567 | E22: 24610 | F22: 24904 | G22: 25129 | H22: 25038 | I22: 24731 | J22: 24543 | K22: 24680 | L22: 24992 | M22: 25137 | N22: 24958 | O22: 298112
A23: 6120 | B23: Dining Director | C23: 4749 | D23: 4728 | E23: 4768 | F23: 4826 | G23: 4838 | H23: 4791 | I23: 4736 | J23: 4734 | K23: 4786 | L23: 4836 | M23: 4829 | N23: 4773 | O23: 57394
A24: 6210 | B24: Housekeeping Wages | C24: 12278 | D24: 12315 | E24: 12466 | F24: 12567 | G24: 12507 | H24: 12352 | I24: 12271 | J24: 12353 | K24: 12508 | L24: 12567 | M24: 12465 | N24: 12314 | O24: 148963
A25: 6310 | B25: Maintenance Wages | C25: 8912 | D25: 8996 | E25: 9102 | F25: 9114 | G25: 9019 | H25: 8921 | I25: 8927 | J25: 9030 | K25: 9118 | L25: 9094 | M25: 8985 | N25: 8910 | O25: 108128
A26: 6410 | B26: Activities Wages | C26: 6209 | D26: 6286 | E26: 6331 | F26: 6294 | G26: 6215 | H26: 6181 | I26: 6229 | J26: 6306 | K26: 6328 | L26: 6271 | M26: 6198 | N26: 6187 | O26: 75035
A27: 6510 | B27: Concierge Wages | C27: 7536 | D27: 7621 | E27: 7621 | F27: 7537 | G27: 7460 | H27: 7475 | I27: 7565 | J27: 7632 | K27: 7603 | L27: 7509 | M27: 7454 | N27: 7497 | O27: 90510
A28: 6610 | B28: Business Office Manager | C28: 5183 | D28: 5214 | E28: 5177 | F28: 5113 | G28: 5091 | H28: 5136 | I28: 5198 | J28: 5210 | K28: 5159 | L28: 5100 | M28: 5098 | N28: 5155 | O28: 61834
A29: 6620 | B29: Executive Director | C29: 8555 | D29: 8545 | E29: 8446 | F29: 8367 | G29: 8394 | H29: 8497 | I29: 8565 | J29: 8522 | K29: 8416 | L29: 8362 | M29: 8420 | N29: 8526 | O29: 101615
A30: 6630 | B30: Sales & Marketing Wages | C30: 7075 | D30: 7019 | E30: 6933 | F30: 6912 | G30: 6978 | H30: 7059 | I30: 7067 | J30: 6993 | K30: 6918 | L30: 6924 | M30: 7005 | N30: 7072 | O30: 83955
... A48: 7990 | B48: Other G&A | C48: 4128 | D48: 4162 | E48: 4340 | F48: 4296 | G48: 4120 | H48: 4175 | I48: 4347 | J48: 4282 | K48: 4114 | L48: 4189 | M48: 4353 | N48: 4268 | O48: 50774
B49: TOTAL OPERATING EXPENSES | C49: 285823 | D49: 286326 | E49: 283277 | F49: 281884 | G49: 285001 | H49: 287726 | I49: 289249 | J49: 287940 | K49: 285361 | L49: 283040 | M49: 284503 | N49: 286547 | O49: 3426677
B51: NET OPERATING INCOME | C51: 110425 | D51: 128635 | E51: 128564 | F51: 120208 | G51: 146294 | H51: 132565 | I51: 132911 | J51: 134889 | K51: 143159 | L51: 137262 | M51: 153133 | N51: 146787 | O51: 1614832
